Workbook
Name LOCAL_MONTH_FORMAT: #REF!
Name LOCAL_DAY_FORMAT: #REF!
Name LOCAL_HOUR_FORMAT: #REF!
Name LOCAL_MINUTE_FORMAT: #REF!
Name _Toc301930478: TestDesign!$B$379
Name LOCAL_TIME_SEPARATOR: #REF!
Name LOCAL_DATE_SEPARATOR: #REF!
Name _Toc301930468: TestDesign!$B$219
Name ACTION: #REF!
Name LOCAL_SECOND_FORMAT: #REF!
Name LOCAL_YEAR_FORMAT: #REF!

Sheet Cover
B2: TEST CASE
B4: Project Name | C4: CellphoneS | F4: Creator | G4: Lê Quang Huy - 22130100
B5: Project Code | C5: CPS | F5: Reviewer/Approver | G5: Trần Thị Thanh Nga
B6: Document Code | C6: =C5&"_TestCase_V0.1" -> CPS_TestCase_V0.1 | F6: Issue Date | G6: 46318
F7: Version | G7: 1.0
B10: Record of change
B11: Effective Date | C11: Version | D11: Change Item | E11: *A,D,M | F11: Change description | G11: Reference
B12: 46318 | C12: 0.1 | E12: A | F12: Tạo test case chức năng Đăng ký / Đăng nhập / Đăng xuất | G12: Assignment 6 - Phân tích & Thiết kế Test Case Tự Động

Sheet Test case List
D1: TEST CASE LIST
B3: Project Name | D3: =Cover!C4 -> CellphoneS
B4: Project Code | D4: =Cover!C5 -> CPS
B5: Test Environment Setup Description | D5: 1. Website: https://cellphones.com.vn (dùng tài khoản test, không tạo giao dịch thật) 2. Trình duyệt: Google Chrome <ghi phiên bản khi chạy>; HĐH: <Windows/macOS> 3. Test data dùng chung: - SDT_DA_DK: SĐT đã có tài khoản; EMAIL_DA_DK: email của tài khoản đó; MK_DUNG: mật khẩu hiện tại (vd: Test@1234); MK_SAI: Sai@9999 - SDT_MOI / EMAIL_MOI: SĐT và email hợp lệ chưa đăng ký, chỉ dùng cho case đăng ký thành công [AUTH-2] (mỗi bộ chỉ dùng 1 lần) - SDT_CHUA_DK / EMAIL_CHUA_DK: SĐT và email hợp lệ chưa đăng ký, dùng cho các case đăng ký lỗi (không tạo tài khoản) - HOTEN: Nguyen Van Test; MK_DK: mật khẩu hợp lệ khi đăng ký (vd: Test@1234) 4. Kết quả mong đợi (Expected Output) là bản thiết kế ban đầu, cần đối chiếu với hành vi thực tế khi chạy test
B8: No | C8: Function Name | D8: Sheet Name | E8: Description | F8: Pre-Condition | G8: Owner
B9: 1 | C9: Đăng ký / Đăng nhập / Đăng xuất | D9: Auth | E9: Đăng ký tài khoản, đăng nhập và đăng xuất | F9: Có tài khoản test đã đăng ký (SDT_DA_DK); có SĐT/email chưa đăng ký để test đăng ký | G9: Lê Quang Huy - 22130100

Sheet TestDesign
A1: Requirement Level 1 | B1: Requirement Level 2 | C1: Requirement Level 3 | D1: Test Criteria | E1: Test Type | F1: Note
A2: 1. Tài khoản & Xác thực | B2: Đăng ký | C2: Điều hướng | D2: Kiểm tra mở form đăng ký từ form đăng nhập | E2: Function | F2: TC: [AUTH-1]
C3: Thành công | D3: Kiểm tra đăng ký với thông tin hợp lệ | E3: Function | F3: TC: [AUTH-2] | Kịch bản chính
D4: Kiểm tra đăng nhập bằng tài khoản vừa đăng ký | E4: Function | F4: TC: [AUTH-3] | Luồng nghiệp vụ
C5: Không thành công | D5: Kiểm tra đăng ký khi để trống tất cả các trường | E5: Function | F5: TC: [AUTH-4]
D6: Kiểm tra đăng ký khi chỉ bỏ trống một trường bắt buộc | E6: Function | F6: TC: [AUTH-5] | Bảng quyết định
D7: Kiểm tra đăng ký với SĐT sai định dạng (thiếu số, chứa chữ, quá dài) | E7: Function | F7: TC: [AUTH-6] | Phân vùng tương đương, giá trị biên
D8: Kiểm tra đăng ký với SĐT đã có tài khoản | E8: Function | F8: TC: [AUTH-7] | Bảng quyết định
D9: Kiểm tra đăng ký với email sai định dạng | E9: Function | F9: TC: [AUTH-8] | Phân vùng tương đương
D10: Kiểm tra đăng ký với email đã có tài khoản | E10: Function | F10: TC: [AUTH-9] | Bảng quyết định
D11: Kiểm tra đăng ký với mật khẩu không đạt yêu cầu | E11: Function | F11: TC: [AUTH-10] | Giá trị biên
D12: Kiểm tra đăng ký khi mật khẩu xác nhận không khớp | E12: Function | F12: TC: [AUTH-11]
D13: Kiểm tra đăng ký khi không tích đồng ý điều khoản | E13: Function | F13: TC: [AUTH-12]
D14: Kiểm tra đăng ký với họ tên không hợp lệ | E14: Function | F14: TC: [AUTH-13] | Phân vùng tương đương, giá trị biên
D15: Kiểm tra đăng ký khi dữ liệu có khoảng trắng đầu/cuối | E15: Function | F15: TC: [AUTH-14]
C16: Bảo mật | D16: Kiểm tra chèn script (XSS) và SQL injection vào form đăng ký | E16: Non-Function | F16: TC: [AUTH-15]
B17: Đăng nhập | C17: Thành công | D17: Kiểm tra đăng nhập với SĐT hợp lệ & mật khẩu đúng | E17: Function | F17: TC: [AUTH-16] | Kịch bản chính
C18: Không thành công | D18: Kiểm tra đăng nhập với SĐT đúng & mật khẩu sai | E18: Function | F18: TC: [AUTH-17] | Bảng quyết định
D19: Kiểm tra đăng nhập với SĐT chưa đăng ký | E19: Function | F19: TC: [AUTH-18] | Bảng quyết định
D20: Kiểm tra đăng nhập khi để trống cả SĐT và mật khẩu | E20: Function | F20: TC: [AUTH-19]
D21: Kiểm tra đăng nhập khi chỉ bỏ trống một trường | E21: Function | F21: TC: [AUTH-20]
D22: Kiểm tra đăng nhập với SĐT sai định dạng (thiếu số, chứa chữ, quá dài) | E22: Function | F22: TC: [AUTH-21] | Phân vùng tương đương, giá trị biên
D23: Kiểm tra đăng nhập khi SĐT có khoảng trắng đầu/cuối | E23: Function | F23: TC: [AUTH-22]
D24: Kiểm tra mật khẩu phân biệt chữ hoa/thường | E24: Function | F24: TC: [AUTH-23]
C25: Giao diện | D25: Kiểm tra ẩn/hiện mật khẩu bằng biểu tượng con mắt | E25: GUI | F25: TC: [AUTH-24]
C26: Bảo mật | D26: Kiểm tra đăng nhập sai nhiều lần liên tiếp (captcha/khóa tạm) | E26: Non-Function | F26: TC: [AUTH-25]
D27: Kiểm tra chèn SQL injection vào ô đăng nhập | E27: Non-Function | F27: TC: [AUTH-26]
D28: Kiểm tra chèn mã script (XSS) vào ô đăng nhập | E28: Non-Function | F28: TC: [AUTH-27]
C29: Phiên đăng nhập | D29: Kiểm tra giữ phiên sau khi tải lại trang / mở lại tab | E29: Function | F29: TC: [AUTH-28]
B30: Đăng xuất | C30: Đăng xuất | D30: Kiểm tra bấm [Đăng xuất] từ menu tài khoản | E30: Function | F30: TC: [AUTH-29]
D31: Kiểm tra bấm Back của trình duyệt sau khi đăng xuất | E31: Function | F31: TC: [AUTH-30]

Sheet Auth
A2: Module Code | B2: AUTH | J2: Passed
A3: Test requirement | B3: Đăng ký / Đăng nhập / Đăng xuất | J3: Failed
A4: Tester | B4: Lê Quang Huy - 22130100 | J4: Blocked
A5: Passed | B5: Failed | C5: Untested | D5: Blocked | E5: Skipped | F5: Number of Test cases | J5: Untested
A6: =COUNTIF(F9:F38,"Passed") -> 24 | B6: =COUNTIF(F9:F38,"Failed") -> 6 | C6: =COUNTIF(F9:F38, "Untested") -> 0 | D6: =COUNTIF(F9:F38,"Blocked") -> 0 | E6: =COUNTIF(F9:F38,"Skipped") -> 0 | F6: =SUMPRODUCT(--(LEN(A9:A996)>0)) -> 30 | J6: Skipped
A7: Hướng dẫn: nhập test case từ dòng 9 (cột ID tự sinh). Result chọn từ danh sách: Passed/Failed/Blocked/Untested/Skipped. Giữ nguyên tên sheet và Module code (B2) để ghép file nhóm.
A8: ID | B8: Test Case Description | C8: Test Case Procedure | D8: Expected Output | E8: Inter-test case Dependence | F8: Result | G8: Test date | H8: Note
A9: =IF(OR(B9<>"",D9<>""),"["&TEXT($B$2,"##")&"-"&TEXT(ROW()-8,"##")&"]","") -> [AUTH-1] | B9: Mở form đăng ký từ form đăng nhập | C9: Pre-condition: + Chưa đăng nhập; đang ở trang chủ https://cellphones.com.vn Step: 1. Bấm [Đăng nhập] trên header để mở form đăng nhập 2. Bấm liên kết [Đăng ký ngay] dưới nút [Đăng nhập] | D9: 1. Form đăng nhập hiển thị có liên kết [Đăng ký ngay] 2. Hiển thị form đăng ký gồm các ô nhập thông tin (họ tên, SĐT, email, mật khẩu), ô đồng ý điều khoản, nút [Đăng ký] và lựa chọn đăng ký nhanh bằng Google | F9: Passed | G9: 46318 | H9: Danh sách trường và nhãn nút cần đối chiếu web thật khi chạy test
A10: =IF(OR(B10<>"",D10<>""),"["&TEXT($B$2,"##")&"-"&TEXT(ROW()-8,"##")&"]","") -> [AUTH-2] | B10: Đăng ký thành công với thông tin hợp lệ | C10: Pre-condition: + Chưa đăng nhập; đang ở trang chủ https://cellphones.com.vn + SDT_MOI và EMAIL_MOI chưa đăng ký tài khoản (xem mục Test data ở sheet Test case List) Test data: - Họ và tên: HOTEN (Nguyen Van Test) - SĐT: SDT_MOI - Email: EMAIL_MOI - Mật khẩu: MK_DK (Test@1234) - Nhập lại mật khẩu: MK_DK (nếu form có ô này) Step: 1. Bấm [Đăng nhập] trên header, sau đó bấm [Đăng ký ngay] để mở form đăng ký 2. Nhập họ tên, SĐT, email hợp lệ 3. Nhập mật khẩu và nhập lại mật khẩu 4. Tích chọn đồng ý điều khoản 5. Bấm [Đăng ký] | D10: 5. Hiển thị thông báo đăng ký thành công; tài khoản được tạo (tự đăng nhập hoặc chuyển về form đăng nhập) | F10: Passed | G10: 46318 | H10: SDT_MOI/EMAIL_MOI chỉ đăng ký được 1 lần, đổi dữ liệu trước lần chạy sau. Nếu web yêu cầu OTP thì nhập mã nhận được và ghi chú lại (chạy thủ công)
A11: =IF(OR(B11<>"",D11<>""),"["&TEXT($B$2,"##")&"-"&TEXT(ROW()-8,"##")&"]","") -> [AUTH-3] | B11: Đăng nhập bằng tài khoản vừa đăng ký | C11: Pre-condition: + Đã đăng ký thành công tài khoản SDT_MOI / MK_DK (xem [AUTH-2]); đang ở trạng thái chưa đăng nhập Test data: - SĐT: SDT_MOI - Mật khẩu: MK_DK Step: 1. Mở form đăng nhập 2. Nhập SĐT SDT_MOI 3. Nhập mật khẩu MK_DK 4. Bấm [Đăng nhập] | D11: 4. Đăng nhập thành công; header hiển thị tên tài khoản vừa đăng ký thay cho nút [Đăng nhập] | E11: [AUTH-2] | F11: Passed | G11: 46318
A12: =IF(OR(B12<>"",D12<>""),"["&TEXT($B$2,"##")&"-"&TEXT(ROW()-8,"##")&"]","") -> [AUTH-4] | B12: Đăng ký khi để trống tất cả các trường | C12: Pre-condition: + Chưa đăng nhập; đang ở trang chủ https://cellphones.com.vn Step: 1. Bấm [Đăng nhập] trên header, sau đó bấm [Đăng ký ngay] để mở form đăng ký 2. Để trống tất cả các ô nhập 3. Bấm [Đăng ký] | D12: 3. Hiển thị thông báo yêu cầu nhập các trường bắt buộc (hoặc nút [Đăng ký] bị vô hiệu); không tạo tài khoản | F12: Passed | G12: 46318
A13: =IF(OR(B13<>"",D13<>""),"["&TEXT($B$2,"##")&"-"&TEXT(ROW()-8,"##")&"]","") -> [AUTH-5] | B13: Đăng ký khi chỉ bỏ trống một trường bắt buộc | C13: Pre-condition: + Chưa đăng nhập; đang ở trang chủ https://cellphones.com.vn Test data: - Bỏ trống lần lượt từng trường: Họ và tên / SĐT / Email / Mật khẩu / Nhập lại mật khẩu - Các trường còn lại hợp lệ: HOTEN, SDT_CHUA_DK, EMAIL_CHUA_DK, MK_DK (xem mục Test data ở sheet Test case List) Step: 1. Bấm [Đăng nhập] trên header, sau đó bấm [Đăng ký ngay] để mở form đăng ký 2. Nhập hợp lệ các trường, chỉ bỏ trống một trường 3. Tích chọn đồng ý điều khoản và bấm [Đăng ký] 4. Lặp lại với từng trường còn lại | D13: 3. Với mỗi lần bỏ trống: báo lỗi yêu cầu nhập đúng trường bị bỏ trống; không tạo tài khoản | F13: Passed | G13: 46318 | H13: Kỹ thuật: bảng quyết định. Nếu trường Email không bắt buộc thì ghi lại hành vi thực tế
A14: =IF(OR(B14<>"",D14<>""),"["&TEXT($B$2,"##")&"-"&TEXT(ROW()-8,"##")&"]","") -> [AUTH-6] | B14: Đăng ký với SĐT sai định dạng | C14: Pre-condition: + Chưa đăng nhập; đang ở trang chủ https://cellphones.com.vn Test data: - SĐT 1: 0912 (thiếu số) - SĐT 2: abc0912345 (chứa chữ) - SĐT 3: 09123456789012 (quá dài) - SĐT 4: 1912345678 (không bắt đầu bằng 0) - Các trường khác hợp lệ (HOTEN, EMAIL_CHUA_DK, MK_DK) Step: 1. Bấm [Đăng nhập] trên header, sau đó bấm [Đăng ký ngay] để mở form đăng ký 2. Lần lượt nhập từng SĐT sai định dạng cùng các trường khác hợp lệ 3. Tích chọn đồng ý điều khoản và bấm [Đăng ký] sau mỗi lần nhập | D14: 3. Với mỗi giá trị: báo SĐT không hợp lệ (hoặc không cho nhập ký tự không phải số); không tạo tài khoản | F14: Passed | G14: 46318 | H14: Kỹ thuật: phân vùng tương đương, giá trị biên về độ dài SĐT
A15: =IF(OR(B15<>"",D15<>""),"["&TEXT($B$2,"##")&"-"&TEXT(ROW()-8,"##")&"]","") -> [AUTH-7] | B15: Đăng ký với SĐT đã có tài khoản | C15: Pre-condition: + Chưa đăng nhập; đang ở trang chủ https://cellphones.com.vn + Có tài khoản test SDT_DA_DK (xem mục Test data ở sheet Test case List) Test data: - SĐT: SDT_DA_DK - Các trường khác hợp lệ (HOTEN, EMAIL_CHUA_DK, MK_DK) Step: 1. Bấm [Đăng nhập] trên header, sau đó bấm [Đăng ký ngay] để mở form đăng ký 2. Nhập SĐT đã đăng ký và các trường khác hợp lệ 3. Tích chọn đồng ý điều khoản và bấm [Đăng ký] | D15: 3. Hiển thị thông báo SĐT đã được đăng ký; không tạo tài khoản mới | F15: Passed | G15: 46318 | H15: Kỹ thuật: bảng quyết định. Nếu web dùng thông báo chung thì vẫn Passed khi không tạo tài khoản mới
A16: =IF(OR(B16<>"",D16<>""),"["&TEXT($B$2,"##")&"-"&TEXT(ROW()-8,"##")&"]","") -> [AUTH-8] | B16: Đăng ký với email sai định dạng | C16: Pre-condition: + Chưa đăng nhập; đang ở trang chủ https://cellphones.com.vn Test data: - Email 1: abc.gmail.com (thiếu @) - Email 2: abc@ (thiếu tên miền) - Email 3: abc@@gmail.com (hai ký tự @) - Email 4: abc @gmail.com (có khoảng trắng) - Các trường khác hợp lệ (HOTEN, SDT_CHUA_DK, MK_DK) Step: 1. Bấm [Đăng nhập] trên header, sau đó bấm [Đăng ký ngay] để mở form đăng ký 2. Lần lượt nhập từng email sai định dạng cùng các trường khác hợp lệ 3. Tích chọn đồng ý điều khoản và bấm [Đăng ký] sau mỗi lần nhập | D16: 3. Với mỗi giá trị: báo email không hợp lệ; không tạo tài khoản | F16: Passed | G16: 46318 | H16: Kỹ thuật: phân vùng tương đương
A17: =IF(OR(B17<>"",D17<>""),"["&TEXT($B$2,"##")&"-"&TEXT(ROW()-8,"##")&"]","") -> [AUTH-9] | B17: Đăng ký với email đã có tài khoản | C17: Pre-condition: + Chưa đăng nhập; đang ở trang chủ https://cellphones.com.vn + Có tài khoản test SDT_DA_DK đã gắn với email EMAIL_DA_DK (xem mục Test data ở sheet Test case List) Test data: - Email: EMAIL_DA_DK - Các trường khác hợp lệ (HOTEN, SDT_CHUA_DK, MK_DK) Step: 1. Bấm [Đăng nhập] trên header, sau đó bấm [Đăng ký ngay] để mở form đăng ký 2. Nhập email đã đăng ký và các trường khác hợp lệ 3. Tích chọn đồng ý điều khoản và bấm [Đăng ký] | D17: 3. Hiển thị thông báo email đã được sử dụng; không tạo tài khoản mới | F17: Passed | G17: 46318 | H17: Kỹ thuật: bảng quyết định
A18: =IF(OR(B18<>"",D18<>""),"["&TEXT($B$2,"##")&"-"&TEXT(ROW()-8,"##")&"]","") -> [AUTH-10] | B18: Đăng ký với mật khẩu không đạt yêu cầu | C18: Pre-condition: + Chưa đăng nhập; đang ở trang chủ https://cellphones.com.vn Test data: - Mật khẩu 1: Ab@1 (quá ngắn) - Mật khẩu 2: abcdefgh (không có chữ hoa, số, ký tự đặc biệt) - Mật khẩu 3: 12345678 (chỉ gồm số) - Các trường khác hợp lệ (HOTEN, SDT_CHUA_DK, EMAIL_CHUA_DK) Step: 1. Bấm [Đăng nhập] trên header, sau đó bấm [Đăng ký ngay] để mở form đăng ký 2. Lần lượt nhập từng mật khẩu (và nhập lại giống hệt ở ô xác nhận) 3. Tích chọn đồng ý điều khoản và bấm [Đăng ký] sau mỗi lần nhập | D18: 3. Với mỗi giá trị: báo mật khẩu không đạt yêu cầu (độ dài tối thiểu/định dạng); không tạo tài khoản | F18: Failed | G18: 46318 | H18: Quy tắc mật khẩu thực tế cần xác minh; nên thử thêm giá trị biên của độ dài tối thiểu
A19: =IF(OR(B19<>"",D19<>""),"["&TEXT($B$2,"##")&"-"&TEXT(ROW()-8,"##")&"]","") -> [AUTH-11] | B19: Đăng ký khi mật khẩu xác nhận không khớp | C19: Pre-condition: + Chưa đăng nhập; đang ở trang chủ https://cellphones.com.vn Test data: - Mật khẩu: MK_DK (Test@1234) - Nhập lại mật khẩu: Test@4321 - Các trường khác hợp lệ (HOTEN, SDT_CHUA_DK, EMAIL_CHUA_DK) Step: 1. Bấm [Đăng nhập] trên header, sau đó bấm [Đăng ký ngay] để mở form đăng ký 2. Nhập các trường hợp lệ, nhập mật khẩu khác nhau ở hai ô mật khẩu 3. Tích chọn đồng ý điều khoản và bấm [Đăng ký] | D19: 3. Hiển thị thông báo mật khẩu xác nhận không khớp; không tạo tài khoản | F19: Passed | G19: 46318 | H19: Chỉ áp dụng nếu form có ô nhập lại mật khẩu; nếu không có thì đặt Skipped
A20: =IF(OR(B20<>"",D20<>""),"["&TEXT($B$2,"##")&"-"&TEXT(ROW()-8,"##")&"]","") -> [AUTH-12] | B20: Đăng ký khi không tích đồng ý điều khoản | C20: Pre-condition: + Chưa đăng nhập; đang ở trang chủ https://cellphones.com.vn Test data: - Tất cả trường hợp lệ (HOTEN, SDT_CHUA_DK, EMAIL_CHUA_DK, MK_DK) Step: 1. Bấm [Đăng nhập] trên header, sau đó bấm [Đăng ký ngay] để mở form đăng ký 2. Nhập tất cả trường hợp lệ 3. Không tích chọn đồng ý điều khoản 4. Bấm [Đăng ký] | D20: 4. Không đăng ký được; hiển thị thông báo yêu cầu đồng ý điều khoản (hoặc nút [Đăng ký] bị vô hiệu); không tạo tài khoản | F20: Passed | G20: 46318
A21: =IF(OR(B21<>"",D21<>""),"["&TEXT($B$2,"##")&"-"&TEXT(ROW()-8,"##")&"]","") -> [AUTH-13] | B21: Đăng ký với họ tên không hợp lệ | C21: Pre-condition: + Chưa đăng nhập; đang ở trang chủ https://cellphones.com.vn Test data: - Họ tên 1: 1234567 (chỉ gồm số) - Họ tên 2: @#$%^&* (ký tự đặc biệt) - Họ tên 3: chuỗi 101 ký tự 'A' (quá dài) - Các trường khác hợp lệ (SDT_CHUA_DK, EMAIL_CHUA_DK, MK_DK) Step: 1. Bấm [Đăng nhập] trên header, sau đó bấm [Đăng ký ngay] để mở form đăng ký 2. Lần lượt nhập từng họ tên không hợp lệ cùng các trường khác hợp lệ 3. Tích chọn đồng ý điều khoản và bấm [Đăng ký] sau mỗi lần nhập | D21: 3. Với mỗi giá trị: báo họ tên không hợp lệ hoặc vượt giới hạn độ dài; không tạo tài khoản | F21: Failed | G21: 46318 | H21: Kỹ thuật: phân vùng tương đương, giá trị biên. Quy tắc họ tên thực tế cần xác minh; nếu web chấp nhận thì ghi lại hành vi thực tế
A22: =IF(OR(B22<>"",D22<>""),"["&TEXT($B$2,"##")&"-"&TEXT(ROW()-8,"##")&"]","") -> [AUTH-14] | B22: Đăng ký khi dữ liệu có khoảng trắng đầu/cuối | C22: Pre-condition: + Chưa đăng nhập; đang ở trang chủ https://cellphones.com.vn Test data: - Họ tên: ' Nguyen Van Test ' - SĐT: ' SDT_CHUA_DK ' (có khoảng trắng đầu và cuối) - Email: ' EMAIL_CHUA_DK ' (có khoảng trắng đầu và cuối) - Mật khẩu: MK_DK Step: 1. Bấm [Đăng nhập] trên header, sau đó bấm [Đăng ký ngay] để mở form đăng ký 2. Nhập các trường có khoảng trắng thừa ở đầu và cuối 3. Tích chọn đồng ý điều khoản và bấm [Đăng ký] | D22: 3. Khoảng trắng thừa được loại bỏ, hoặc hệ thống báo trường không hợp lệ; không xảy ra lỗi hệ thống | F22: Passed | G22: 46318 | H22: Hành vi chưa xác minh trên web thật. Nếu đăng ký thành công thì SĐT/email đã bị dùng, đổi dữ liệu trước lần chạy sau
A23: =IF(OR(B23<>"",D23<>""),"["&TEXT($B$2,"##")&"-"&TEXT(ROW()-8,"##")&"]","") -> [AUTH-15] | B23: Bảo mật: chèn script (XSS) và SQL injection vào form đăng ký | C23: Pre-condition: + Chưa đăng nhập; đang ở trang chủ https://cellphones.com.vn Test data: - Họ tên: <script>alert(1)</script> - Email: ' OR '1'='1 - SĐT: SDT_CHUA_DK - Mật khẩu: MK_DK Step: 1. Bấm [Đăng nhập] trên header, sau đó bấm [Đăng ký ngay] để mở form đăng ký 2. Nhập dữ liệu chèn mã vào ô Họ tên và ô Email, các trường khác hợp lệ 3. Tích chọn đồng ý điều khoản và bấm [Đăng ký] | D23: 3. Không xuất hiện hộp thoại alert, script không được thực thi; báo dữ liệu không hợp lệ; không tạo tài khoản; không lộ lỗi hệ thống (SQL error, stack trace) | F23: Passed | G23: 46318 | H23: Kiểm thử bảo mật cơ bản, chỉ nhập vào form đăng ký thông thường
A24: =IF(OR(B24<>"",D24<>""),"["&TEXT($B$2,"##")&"-"&TEXT(ROW()-8,"##")&"]","") -> [AUTH-16] | B24: Đăng nhập thành công với SĐT và mật khẩu hợp lệ | C24: Pre-condition: + Chưa đăng nhập; đang ở trang chủ https://cellphones.com.vn + Có tài khoản test SDT_DA_DK / MK_DUNG (xem mục Test data ở sheet Test case List) Test data: - SĐT: SDT_DA_DK - Mật khẩu: MK_DUNG Step: 1. Bấm [Đăng nhập] trên header để mở form đăng nhập 2. Nhập SĐT hợp lệ vào ô SĐT 3. Nhập mật khẩu đúng vào ô Mật khẩu 4. Bấm [Đăng nhập] | D24: 1. Form đăng nhập hiển thị gồm ô SĐT, ô Mật khẩu và nút [Đăng nhập] 4. Đăng nhập thành công, form đóng lại; header hiển thị tên tài khoản thay cho nút [Đăng nhập] | F24: Passed | G24: 46318 | H24: Vị trí/nhãn nút cần đối chiếu web thật khi chạy test
A25: =IF(OR(B25<>"",D25<>""),"["&TEXT($B$2,"##")&"-"&TEXT(ROW()-8,"##")&"]","") -> [AUTH-17] | B25: Đăng nhập với SĐT đúng, mật khẩu sai | C25: Pre-condition: + Chưa đăng nhập; đang ở trang chủ https://cellphones.com.vn + Có tài khoản test SDT_DA_DK / MK_DUNG (xem mục Test data ở sheet Test case List) Test data: - SĐT: SDT_DA_DK - Mật khẩu: MK_SAI (Sai@9999) Step: 1. Mở form đăng nhập 2. Nhập SĐT đã đăng ký 3. Nhập mật khẩu sai 4. Bấm [Đăng nhập] | D25: 4. Hiển thị thông báo sai thông tin đăng nhập; không đăng nhập; vẫn ở trạng thái chưa đăng nhập | F25: Passed | G25: 46318 | H25: Đối chiếu nội dung thông báo lỗi thực tế
A26: =IF(OR(B26<>"",D26<>""),"["&TEXT($B$2,"##")&"-"&TEXT(ROW()-8,"##")&"]","") -> [AUTH-18] | B26: Đăng nhập với SĐT chưa đăng ký | C26: Pre-condition: + Chưa đăng nhập; đang ở trang chủ https://cellphones.com.vn + Có tài khoản test SDT_DA_DK / MK_DUNG (xem mục Test data ở sheet Test case List) Test data: - SĐT: SDT_CHUA_DK - Mật khẩu: MK_DUNG Step: 1. Mở form đăng nhập 2. Nhập SĐT chưa có tài khoản 3. Nhập mật khẩu bất kỳ 4. Bấm [Đăng nhập] | D26: 4. Hiển thị thông báo tài khoản không tồn tại (hoặc sai thông tin đăng nhập); không đăng nhập | F26: Passed | G26: 46318 | H26: Nếu web dùng chung 1 thông báo cho sai SĐT và sai mật khẩu (tránh lộ tài khoản) thì vẫn Passed
A27: =IF(OR(B27<>"",D27<>""),"["&TEXT($B$2,"##")&"-"&TEXT(ROW()-8,"##")&"]","") -> [AUTH-19] | B27: Đăng nhập khi để trống cả SĐT và mật khẩu | C27: Pre-condition: + Chưa đăng nhập; đang ở trang chủ https://cellphones.com.vn Step: 1. Mở form đăng nhập 2. Để trống ô SĐT và ô Mật khẩu 3. Bấm [Đăng nhập] | D27: 3. Hiển thị thông báo yêu cầu nhập SĐT và mật khẩu; không gửi yêu cầu đăng nhập | F27: Passed | G27: 46318
A28: =IF(OR(B28<>"",D28<>""),"["&TEXT($B$2,"##")&"-"&TEXT(ROW()-8,"##")&"]","") -> [AUTH-20] | B28: Đăng nhập khi chỉ bỏ trống một trường (SĐT hoặc mật khẩu) | C28: Pre-condition: + Chưa đăng nhập; đang ở trang chủ https://cellphones.com.vn + Có tài khoản test SDT_DA_DK / MK_DUNG (xem mục Test data ở sheet Test case List) Test data: - Lần 1: SĐT để trống; Mật khẩu: MK_DUNG - Lần 2: SĐT: SDT_DA_DK; Mật khẩu để trống Step: 1. Mở form đăng nhập 2. Lần 1: để trống ô SĐT, nhập mật khẩu, bấm [Đăng nhập] 3. Làm mới form. Lần 2: nhập SĐT, để trống mật khẩu, bấm [Đăng nhập] | D28: 2. Báo lỗi yêu cầu nhập SĐT; không đăng nhập 3. Báo lỗi yêu cầu nhập mật khẩu; không đăng nhập | F28: Passed | G28: 46318
A29: =IF(OR(B29<>"",D29<>""),"["&TEXT($B$2,"##")&"-"&TEXT(ROW()-8,"##")&"]","") -> [AUTH-21] | B29: Đăng nhập với SĐT sai định dạng | C29: Pre-condition: + Chưa đăng nhập; đang ở trang chủ https://cellphones.com.vn + Có tài khoản test SDT_DA_DK / MK_DUNG (xem mục Test data ở sheet Test case List) Test data: - SĐT 1: 0912 (thiếu số) - SĐT 2: abc0912345 (chứa chữ) - SĐT 3: 09123456789012 (quá dài) - Mật khẩu: MK_DUNG Step: 1. Mở form đăng nhập 2. Lần lượt nhập từng SĐT sai định dạng cùng mật khẩu MK_DUNG 3. Bấm [Đăng nhập] sau mỗi lần nhập | D29: 3. Với mỗi giá trị: báo SĐT không hợp lệ (hoặc không cho nhập ký tự không phải số); không đăng nhập | F29: Passed | G29: 46318 | H29: Kỹ thuật: phân vùng tương đương, giá trị biên về độ dài SĐT
A30: =IF(OR(B30<>"",D30<>""),"["&TEXT($B$2,"##")&"-"&TEXT(ROW()-8,"##")&"]","") -> [AUTH-22] | B30: Đăng nhập khi SĐT có khoảng trắng đầu/cuối | C30: Pre-condition: + Chưa đăng nhập; đang ở trang chủ https://cellphones.com.vn + Có tài khoản test SDT_DA_DK / MK_DUNG (xem mục Test data ở sheet Test case List) Test data: - SĐT: ' 0912345678 ' (SDT_DA_DK có khoảng trắng đầu và cuối) - Mật khẩu: MK_DUNG Step: 1. Mở form đăng nhập 2. Nhập SĐT có khoảng trắng thừa ở đầu và cuối 3. Nhập mật khẩu đúng 4. Bấm [Đăng nhập] | D30: 4. Khoảng trắng thừa được loại bỏ và đăng nhập thành công | F30: Failed | G30: 46318 | H30: Hành vi chưa xác minh trên web thật; nếu web báo lỗi định dạng thì ghi lại khi chạy
A31: =IF(OR(B31<>"",D31<>""),"["&TEXT($B$2,"##")&"-"&TEXT(ROW()-8,"##")&"]","") -> [AUTH-23] | B31: Mật khẩu phân biệt chữ hoa/chữ thường | C31: Pre-condition: + Chưa đăng nhập; đang ở trang chủ https://cellphones.com.vn + Có tài khoản test SDT_DA_DK / MK_DUNG (xem mục Test data ở sheet Test case List) Test data: - SĐT: SDT_DA_DK - Mật khẩu: MK_DUNG đổi kiểu chữ (vd: Test@1234 thành test@1234) Step: 1. Mở form đăng nhập 2. Nhập SĐT đã đăng ký 3. Nhập mật khẩu đúng ký tự nhưng sai chữ hoa/thường 4. Bấm [Đăng nhập] | D31: 4. Đăng nhập thất bại; hiển thị thông báo sai thông tin đăng nhập | F31: Passed | G31: 46318 | H31: Giả định mật khẩu phân biệt hoa/thường (thông lệ chung)
A32: =IF(OR(B32<>"",D32<>""),"["&TEXT($B$2,"##")&"-"&TEXT(ROW()-8,"##")&"]","") -> [AUTH-24] | B32: Ẩn/hiện mật khẩu bằng biểu tượng con mắt | C32: Pre-condition: + Chưa đăng nhập; đang ở trang chủ https://cellphones.com.vn Test data: - Mật khẩu: MK_DUNG Step: 1. Mở form đăng nhập 2. Nhập mật khẩu vào ô Mật khẩu 3. Bấm biểu tượng hiện/ẩn mật khẩu 4. Bấm biểu tượng thêm một lần nữa | D32: 2. Mật khẩu hiển thị dạng dấu chấm 3. Mật khẩu hiển thị dạng ký tự rõ 4. Mật khẩu trở lại dạng dấu chấm | F32: Passed | G32: 46318 | H32: Chỉ áp dụng nếu form có biểu tượng hiện/ẩn; nếu không có thì đặt Skipped
A33: =IF(OR(B33<>"",D33<>""),"["&TEXT($B$2,"##")&"-"&TEXT(ROW()-8,"##")&"]","") -> [AUTH-25] | B33: Đăng nhập sai mật khẩu nhiều lần liên tiếp | C33: Pre-condition: + Chưa đăng nhập; đang ở trang chủ https://cellphones.com.vn + Có tài khoản test SDT_DA_DK / MK_DUNG (xem mục Test data ở sheet Test case List) Test data: - SĐT: SDT_DA_DK - Mật khẩu: MK_SAI (5 lần liên tiếp), sau đó MK_DUNG Step: 1. Mở form đăng nhập 2. Đăng nhập với MK_SAI, lặp lại 5 lần liên tiếp 3. Đăng nhập tiếp với mật khẩu đúng MK_DUNG | D33: 2. Mỗi lần báo sai thông tin; sau số lần quy định hệ thống hiển thị captcha / giới hạn thử / khóa tạm thời (ghi lại ngưỡng thực tế) 3. Nếu đang bị khóa/yêu cầu captcha: không đăng nhập được cho đến khi hết thời gian khóa hoặc qua captcha | F33: Passed | G33: 46318 | H33: Có thể khóa tạm tài khoản test. Nếu web không giới hạn số lần thử thì ghi nhận là rủi ro bảo mật
A34: =IF(OR(B34<>"",D34<>""),"["&TEXT($B$2,"##")&"-"&TEXT(ROW()-8,"##")&"]","") -> [AUTH-26] | B34: Bảo mật: chèn SQL injection vào ô đăng nhập | C34: Pre-condition: + Chưa đăng nhập; đang ở trang chủ https://cellphones.com.vn Test data: - SĐT: ' OR '1'='1 - Mật khẩu: ' OR '1'='1 Step: 1. Mở form đăng nhập 2. Nhập chuỗi SQL injection vào ô SĐT và ô Mật khẩu 3. Bấm [Đăng nhập] | D34: 3. Không đăng nhập được; hiển thị thông báo SĐT không hợp lệ/sai thông tin; không lộ lỗi hệ thống (SQL error, stack trace) | F34: Passed | G34: 46318 | H34: Kiểm thử bảo mật cơ bản, chỉ nhập vào form đăng nhập thông thường
A35: =IF(OR(B35<>"",D35<>""),"["&TEXT($B$2,"##")&"-"&TEXT(ROW()-8,"##")&"]","") -> [AUTH-27] | B35: Bảo mật: chèn mã script (XSS) vào ô đăng nhập | C35: Pre-condition: + Chưa đăng nhập; đang ở trang chủ https://cellphones.com.vn Test data: - SĐT: <script>alert(1)</script> - Mật khẩu: MK_DUNG Step: 1. Mở form đăng nhập 2. Nhập thẻ script vào ô SĐT, nhập mật khẩu 3. Bấm [Đăng nhập] | D35: 3. Không xuất hiện hộp thoại alert, script không được thực thi; báo SĐT không hợp lệ; không đăng nhập | F35: Passed | G35: 46318
A36: =IF(OR(B36<>"",D36<>""),"["&TEXT($B$2,"##")&"-"&TEXT(ROW()-8,"##")&"]","") -> [AUTH-28] | B36: Giữ phiên đăng nhập sau khi tải lại trang / mở lại tab | C36: Pre-condition: + Đã đăng nhập thành công (xem [AUTH-16]) Step: 1. Nhấn F5 để tải lại trang 2. Đóng tab, mở lại https://cellphones.com.vn trong cùng trình duyệt | D36: 1. Vẫn ở trạng thái đã đăng nhập 2. Vẫn ở trạng thái đã đăng nhập (nếu phiên còn hiệu lực) | E36: [AUTH-16] | F36: Failed | G36: 46318 | H36: Thời hạn phiên đăng nhập thực tế cần xác minh
A37: =IF(OR(B37<>"",D37<>""),"["&TEXT($B$2,"##")&"-"&TEXT(ROW()-8,"##")&"]","") -> [AUTH-29] | B37: Đăng xuất thành công | C37: Pre-condition: + Đã đăng nhập thành công (xem [AUTH-16]) Step: 1. Bấm vào tên tài khoản trên header (hoặc mở menu tài khoản) 2. Bấm [Đăng xuất] | D37: 1. Menu tài khoản hiển thị có mục [Đăng xuất] 2. Đăng xuất thành công; header hiển thị lại nút [Đăng nhập]; thông tin tài khoản không còn hiển thị | E37: [AUTH-16] | F37: Failed | G37: 46318
A38: =IF(OR(B38<>"",D38<>""),"["&TEXT($B$2,"##")&"-"&TEXT(ROW()-8,"##")&"]","") -> [AUTH-30] | B38: Bấm Back của trình duyệt sau khi đăng xuất | C38: Pre-condition: + Vừa đăng xuất thành công (xem [AUTH-29]) Step: 1. Bấm nút Back của trình duyệt (nhiều lần) 2. Truy cập trực tiếp trang thông tin tài khoản bằng URL/menu | D38: 1. Không hiển thị lại thông tin tài khoản của người dùng đã đăng xuất 2. Hệ thống yêu cầu đăng nhập (hoặc chuyển về trang chủ/đăng nhập) | E38: [AUTH-29] | F38: Failed | G38: 46318 | H38: Kiểm tra cache trang sau khi đăng xuất
A39: =IF(OR(B39<>"",D39<>""),"["&TEXT($B$2,"##")&"-"&TEXT(ROW()-8,"##")&"]","")
A40: =IF(OR(B40<>"",D40<>""),"["&TEXT($B$2,"##")&"-"&TEXT(ROW()-8,"##")&"]","")
A41: =IF(OR(B41<>"",D41<>""),"["&TEXT($B$2,"##")&"-"&TEXT(ROW()-8,"##")&"]","")
...

Sheet Test Report
B1: TEST REPORT
B3: Project Name | C3: =Cover!C4 -> CellphoneS | E3: Creator | G3: Lê Quang Huy - 22130100
B4: Project Code | C4: =Cover!C5 -> CPS | E4: Reviewer/Approver | G4: Trần Thị Thanh Nga
B5: Document Code | C5: =C4&"_"&"Test Report"&"_"&"v0.1" -> CPS_Test Report_v0.1 | E5: Issue Date | G5: 46318
B6: Notes | C6: Release 1 gồm module Auth (Đăng ký / Đăng nhập / Đăng xuất). Chưa chạy test.
B10: No | C10: Module code | D10: Pass | E10: Fail | F10: Untested | G10: Blocked | H10: Skipped | I10: Number of test cases
B11: 1 | C11: =Auth!B2 -> AUTH | D11: =Auth!A6 -> 24 | E11: =Auth!B6 -> 6 | F11: =Auth!C6 -> 0 | G11: =Auth!D6 -> 0 | H11: =Auth!E6 -> 0 | I11: =SUM(D11:H11) -> 30
C13: Sub total | D13: =SUM(D11:D12) -> 24 | E13: =SUM(E11:E12) -> 6 | F13: =SUM(F11:F12) -> 0 | G13: =SUM(G11:G12) -> 0 | H13: =SUM(H11:H12) -> 0 | I13: =SUM(I11:I12) -> 30
C15: Test coverage | E15: =(I13-F13)/I13 -> 1 | F15: %
C16: Test successful coverage | E16: =IF((D13+E13)=0,0,D13*100/(D13+E13)) -> 80 | F16: %
